{"qid": "HumanEval/0", "status": "error", "error_type": "Exception", "error_message": "unknown_error: cannot access local variable 'reprompt' where it is not associated with a value", "retryable": true, "timestamp": 1758784221.217037, "datetime": "2025-09-25T00:10:21.217037", "checkpoint_time": 1758784221.2170398, "checkpoint_datetime": "2025-09-25T00:10:21.217041"}
{"qid": "HumanEval/0", "status": "error", "error_type": "UnboundLocalError", "error_message": "cannot access local variable 'reprompt' where it is not associated with a value", "retryable": true, "timestamp": 1758784221.7203782, "datetime": "2025-09-25T00:10:21.720379", "error_context": {"provider": "mixed", "model": "gpt-4o-mini", "experiment_id": "ensemble_heterogeneous_ensemble_20250925_000933", "learner_type": "ensemble"}, "checkpoint_time": 1758784221.720394, "checkpoint_datetime": "2025-09-25T00:10:21.720395"}
{"qid": "HumanEval/1", "status": "error", "error_type": "Exception", "error_message": "unknown_error: cannot access local variable 'reprompt' where it is not associated with a value", "retryable": true, "timestamp": 1758784270.0988789, "datetime": "2025-09-25T00:11:10.098879", "checkpoint_time": 1758784270.0988832, "checkpoint_datetime": "2025-09-25T00:11:10.098883"}
{"qid": "HumanEval/1", "status": "error", "error_type": "UnboundLocalError", "error_message": "cannot access local variable 'reprompt' where it is not associated with a value", "retryable": true, "timestamp": 1758784270.920703, "datetime": "2025-09-25T00:11:10.920706", "error_context": {"provider": "mixed", "model": "gpt-4o-mini", "experiment_id": "ensemble_heterogeneous_ensemble_20250925_000933", "learner_type": "ensemble"}, "checkpoint_time": 1758784270.920732, "checkpoint_datetime": "2025-09-25T00:11:10.920732"}
{"qid": "HumanEval/2", "status": "error", "error_type": "Exception", "error_message": "unknown_error: cannot access local variable 'reprompt' where it is not associated with a value", "retryable": true, "timestamp": 1758784314.731953, "datetime": "2025-09-25T00:11:54.731953", "checkpoint_time": 1758784314.731957, "checkpoint_datetime": "2025-09-25T00:11:54.731957"}
{"qid": "HumanEval/2", "status": "error", "error_type": "UnboundLocalError", "error_message": "cannot access local variable 'reprompt' where it is not associated with a value", "retryable": true, "timestamp": 1758784317.027254, "datetime": "2025-09-25T00:11:57.027259", "error_context": {"provider": "mixed", "model": "gpt-4o-mini", "experiment_id": "ensemble_heterogeneous_ensemble_20250925_000933", "learner_type": "ensemble"}, "checkpoint_time": 1758784317.027284, "checkpoint_datetime": "2025-09-25T00:11:57.027284"}
{"qid": "HumanEval/3", "status": "error", "error_type": "Exception", "error_message": "unknown_error: cannot access local variable 'reprompt' where it is not associated with a value", "retryable": true, "timestamp": 1758784355.626663, "datetime": "2025-09-25T00:12:35.626663", "checkpoint_time": 1758784355.626667, "checkpoint_datetime": "2025-09-25T00:12:35.626667"}
{"qid": "HumanEval/3", "status": "error", "error_type": "UnboundLocalError", "error_message": "cannot access local variable 'reprompt' where it is not associated with a value", "retryable": true, "timestamp": 1758784359.596471, "datetime": "2025-09-25T00:12:39.596475", "error_context": {"provider": "mixed", "model": "gpt-4o-mini", "experiment_id": "ensemble_heterogeneous_ensemble_20250925_000933", "learner_type": "ensemble"}, "checkpoint_time": 1758784359.596498, "checkpoint_datetime": "2025-09-25T00:12:39.596499"}
{"qid": "HumanEval/4", "status": "error", "error_type": "Exception", "error_message": "unknown_error: cannot access local variable 'reprompt' where it is not associated with a value", "retryable": true, "timestamp": 1758784407.628758, "datetime": "2025-09-25T00:13:27.628758", "checkpoint_time": 1758784407.628762, "checkpoint_datetime": "2025-09-25T00:13:27.628762"}
{"qid": "HumanEval/4", "status": "error", "error_type": "UnboundLocalError", "error_message": "cannot access local variable 'reprompt' where it is not associated with a value", "retryable": true, "timestamp": 1758784415.443234, "datetime": "2025-09-25T00:13:35.443243", "error_context": {"provider": "mixed", "model": "gpt-4o-mini", "experiment_id": "ensemble_heterogeneous_ensemble_20250925_000933", "learner_type": "ensemble"}, "checkpoint_time": 1758784415.443291, "checkpoint_datetime": "2025-09-25T00:13:35.443292"}
{"qid": "HumanEval/5", "status": "error", "error_type": "Exception", "error_message": "unknown_error: cannot access local variable 'reprompt' where it is not associated with a value", "retryable": true, "timestamp": 1758784457.2339761, "datetime": "2025-09-25T00:14:17.233977", "checkpoint_time": 1758784457.233981, "checkpoint_datetime": "2025-09-25T00:14:17.233981"}
